Workbook

Sheet FIN_ASSUMPTIONS_tong_hop
A1: FIN_ASSUMPTIONS — bộ số sau khi sửa (09/10/2026, khớp Final Plan v5 và FINAL PRODUCT V5)
A2: Xanh dương = nhập tay; đen = công thức; xanh lá = lấy từ sheet khác. Trạng thái: CHỐT / ĐỀ XUẤT (chờ nhóm duyệt) / MỞ (chưa có số).
A4: Field | B4: Giá trị | C4: Std (Monte Carlo) | D4: Cách rút mẫu | E4: Trạng thái | F4: Nguồn / cách tính
A5: interest_rate_promo_pct — 6 tháng | B5: ='Lãi suất vay nhà - npp'!C10 -> 0.077 | E5: CHỐT | F5: MB CN Vạn Phúc (ảnh văn bản gốc)
A6: interest_rate_promo_pct — 12 tháng | B6: ='Lãi suất vay nhà - npp'!C11 -> 0.083 | E6: CHỐT | F6: MB CN Vạn Phúc
A7: interest_rate_promo_pct — 18 tháng | B7: ='Lãi suất vay nhà - npp'!C12 -> 0.085 | E7: CHỐT | F7: MB CN Vạn Phúc
A8: interest_rate_promo_pct — 24 tháng | B8: ='Lãi suất vay nhà - npp'!C13 -> 0.09 | E8: CHỐT | F8: MB CN Vạn Phúc
A9: float_rate_margin_year1_pct | B9: =Lai_tham_chieu!B7 -> 0.015 | E9: CHỐT | F9: MB CN Vạn Phúc — năm đầu SAU ưu đãi
A10: float_rate_margin_from_year2_pct | B10: =Lai_tham_chieu!B8 -> 0.035 | E10: CHỐT | F10: MB CN Vạn Phúc
A11: interest_rate_float_ref_pct | B11: =Lai_tham_chieu!B2 -> 0.105 | C11: 0.0075 | D11: per_path | E11: CHỐT (nhóm quyết 08/10; số ngoại suy) | F11: Ngoại suy: lãi thả nổi thị trường 13–15% (Thanh Niên 25/08/2026, Dân trí 24/08/2026) − biên độ MB 3,5%; xem sheet Lai_tham_chieu. Cần xác nhận với MB
A12: rate_adjustment_frequency_months | B12: 3 | E12: CHỐT | F12: MB CN Vạn Phúc
A13: grace_period_months | B13: 24 | E13: CHỐT | F13: MB CN Vạn Phúc
A14: prepayment_fee_pct (năm 1-5 / từ năm 6) | B14: 1% / 0% | E14: CHỐT | F14: MB CN Vạn Phúc
A15: max_loan_to_value_pct — base / boom / downturn | B15: 80% / 80% / 70% | E15: CHỐT | F15: Base & Boom 80% = MB CN Vạn Phúc tối đa (mọi thông số vay lấy theo gói MB, nên Boom không dùng 100% của VCB); Downturn 70% = ngân hàng siết, gói VCB Nhà mới thành đạt. Sửa 08/10 (Boom 100% → 80%).
A16: bank_max_term_months | B16: 360 | E16: CHỐT | F16: MB CN Vạn Phúc
A17: max_borrower_age (tuổi tối đa khi kết thúc khoản vay; độ nhạy 65 / 75) | B17: 70 | E17: CHỐT (nhóm quyết 08/10) | F17: Cách tính: tuổi người lớn hơn = max(tuổi 1, tuổi 2); kỳ hạn tối đa = (70 − tuổi người lớn hơn) × 12, không quá 360 tháng; chặn nếu ≤ 24 tháng. Nguồn chính VIB (22/07/2025): https://www.vib.com.vn/vn/cam-nang/vay/vay-bat-dong-san/vay-mua-nha-duoc-bao-nhieu-nam ; Cake: https://cake.vn/tin-tuc/tai-chinh/vay-the-chap-toi-da-duoc-bao-nhieu-nam ; Onlinebank–MB: https://onlinebank.com.vn/sp/vay-mua-nha-du-an-mb/ ; Standard Chartered: https://www.sc.com/vn/loans/mortgage/ . Độ nhạy 65 (VPBank) / 75 (PVcomBank, NCB). Luật “người lớn tuổi hơn” khi vay chung là GIẢ ĐỊNH thận trọng của nhóm (chưa ngân hàng nào ghi rõ); cần MB Vạn Phúc xác nhận.
A18: buy_closing_costs_pct | B18: 0.026 | E18: CHỐT (có nguồn) | F18: Gồm: phí bảo trì 2% (Khoản 1 Điều 152 Luật Nhà ở 2023, hiệu lực 01/08/2024: https://hethongphapluat.com/law-no-27-2023-qh15-dated-december-27-2023-on-housing/dieu-152 ; https://thuvienphapluat.vn/phap-luat-nha-dat/nguoi-mua-can-ho-chung-cu-co-bat-buoc-phai-dong-phi-bao-tri-chung-cu-khong-8987.html ; https://thuviennhadat.vn/phap-ly-nha-dat/nguoi-mua-chung-cu-phai-dong-2-kinh-phi-bao-tri-chung-cu-dung-khong-633637.html ; NĐ 99/2015 hết hiệu lực 01/08/2024, thay bằng NĐ 95/2024 theo QĐ 99/QĐ-BXD: https://caselaw.vn/van-ban-phap-luat/506072-quyet-dinh-so-99-qd-bxd-ngay-24-01-2025-cua-bo-truong-bo-xay-dung-cong-bo-danh-muc-van-ban-quy-pham-phap-luat-het-hieu-luc-toan-bo-hoac-mot-phan-thuoc-linh-vuc-quan-ly-nha-nuoc-cua-bo-xay-dung-nam-2024) + lệ phí trước bạ 0,5% (K1 Đ8 NĐ 10/2022, sửa bởi NĐ 175/2025; khai theo NĐ 373/2025: https://thuvienphapluat.vn/phap-luat-nha-dat/toan-bo-19-truong-hop-duoc-mien-le-phi-truoc-ba-nha-dat-2026-14320.html ; https://thuvienphapluat.vn/phap-luat-nha-dat/ho-so-khai-le-phi-truoc-ba-nha-dat-moi-nhat-2026-chuan-nghi-dinh-373-2025-nd-cp-14436.html) + công chứng ~0,05-0,07% theo bậc (TT 257/2016 sửa bởi TT 111/2017: https://luatvietnam.vn/hanh-chinh/muc-phi-cong-chung-moi-nhat-570-21497-article.html). Dùng trong kiểm tra tiền trả trước tối thiểu (B4: tiền trả trước thật = tiết kiệm − phí 2,6% − quỹ dự phòng) và trong giới hạn dpLimit = (tiết kiệm − quỹ) ÷ 0,226 của Plan B (B2.1). Lưu ý: Điều 152 chỉ áp dụng cho người mua từ chủ đầu tư; listing của nhóm là căn bán lại nên phí thực tế có thể chỉ ~0,56%. Model giữ 2,6% như mức thận trọng, nên điều kiện tiền trả trước có thể khắt khe hơn thực tế.
A19: property_annual_appreciation_pct | B19: PA2 (CHỐT): 20,43% → 8,38%, τ = 3,24 năm | C19: 0.04 | D19: per_path | E19: CHỐT (PA2); PA1 19% cố định = cận trên đối chiếu | F19: g(t) = 8,38% + (20,43% − 8,38%)·e^(−t/3,24). Điểm đầu 20,43% = CAGR sơ cấp Hà Nội 2020-2025 (sheet giá bds; CafeF/Cushman & Wakefield). Điểm cuối 8,38% = CPI 3,09% + tăng GDP thực/người (World Bank). τ = 3,24 hiệu chỉnh để trung bình 10 năm = 12,66% (CAGR 2016-2025, sheet giá bds). Kết quả: TB 10 năm 12,66%, CAGR 30 năm 9,86%. Độ nhạy τ = 1 / 3,24 / 6,5; PA1 19%/năm cố định (×185 sau 30 năm) giữ làm cận trên.
A20: rent_annual_growth_pct | B20: 6% (độ nhạy 3% / 7% / 10%) | C20: 0.0125 | D20: per_path | E20: CHỐT (09/10) | F20: Chốt 09/10: base 6%/năm; độ nhạy 3% / 7% / 10%; σ = 1,25 điểm % rút 1 lần/đường = (10% − 5%) / 4. Gần tốc độ tăng thu nhập ĐBSH 5,56% nên tiền thuê/thu nhập sau 30 năm chỉ tăng nhẹ (30% → 34%); cao hơn CPI 3,09%; nằm ở cận dưới khoảng 5–10% của VnExpress 15/08/2025 (giá chào, nhiều chung cư 10–15%) và Vietnambiz 14/04/2025 (đi ngang ~3 năm). Không có chuỗi giá thuê căn hộ thường, 6% là mức phán đoán có lý lẽ, không phải số đo trực tiếp (Hạn chế #6). Luôn bật cùng lúc tăng thu nhập và CPI. 3% dùng cho Downturn, 10% cho Boom.
A21: income_annual_growth_pct | B21: ='Biến động thu nhập household (k'!H2 -> 0.055620076 | C21: ='Biến động thu nhập household (k'!H3 -> 0.057109401 | D21: per_year | E21: CHỐT | F21: Chuỗi Đồng bằng sông Hồng — NSO, Khảo sát mức sống dân cư (KSMS) 2024, trang 283; quy đổi hằng năm 2019-2024 (danh nghĩa).
A22: living_cost_annual_growth_pct (CPI) | B22: ='Inflation - kan'!B6 -> 0.030920093 | E22: ĐỀ XUẤT | F22: World Bank CPI 2016-2025
A23: savings (kênh) | B23: ='Lãi huy động (kan)'!I8 -> 0.065 | C23: ='Lãi huy động (kan)'!I7 -> 0.0081608823 | D23: per_path | E23: ĐỀ XUẤT | F23: LSHĐ 6-12 tháng mức cao nhất 2016-2026 (FiinPro) — CẬN TRÊN
A24: stocks (kênh, VN-Index) | B24: ='VNIndex return - npp'!Q5 -> 0.079904483 | C24: ='VNIndex return - npp'!Q6 -> 0.19297193 | D24: per_year | E24: ĐỀ XUẤT | F24: VN-Index 05/2021-08/2026 (investing.com), đã sửa ngày; chưa gồm cổ tức
A25: bonds (kênh, TPCP 10 năm) | B25: ='Return Bond (kan)'!H5 -> 0.040218182 | C25: ='Return Bond (kan)'!H4 -> 0.013650701 | D25: per_path | E25: ĐỀ XUẤT | F25: FiinPro 2016-2026; std của mức lợi suất
A26: gold (kênh, SJC) | B26: ='Giá vàng SJC - kan'!F13 -> 0.11115046 | C26: ='Giá vàng SJC - kan'!F7 -> 0.14125874 | D26: per_year | E26: CHỐT 07/10 (base bỏ 2025; 14,89% = độ nhạy) | F26: FiinPro giá bán SJC. Base = TB tháng × 12 giai đoạn 02/2016–12/2024 (bỏ cú tăng 2025 +81,5%). Độ nhạy: 14,89% (01/2016–09/2026, ô F6 sheet vàng). σ giữ 14,13% (cả chuỗi) cho thận trọng.
A27: Lợi suất cho thuê năm 0 (kiểm tra B5.1) | B27: 2,3% (data nhóm) – 3,74% (GPG 2PN) | E27: ĐỀ XUẤT | F27: Trung vị 71 tòa có cả tin mua & thuê (DATA.xlsx); GPG Q3/2025 rental yields
A28: safety_margin_min_pct (<35tr/35-49/50-74/≥75tr) | B28: 40% / 35% / 30% / 25% | E28: CHỐT | F28: Đề xuất nhóm; bậc 25% nội suy; CFPB/DNSE chỉ tham khảo. Cách C (chốt 07/10): bậc tra theo thu nhập quy về tiền hôm nay = thu nhập danh nghĩa ÷ lạm phát cộng dồn (CPI 3,09%/năm), xét từng tháng của kỳ vay; tháng xấu nhất = khoảng cách nhỏ nhất giữa tỷ lệ dư và ngưỡng. V3 (09/10): thêm tùy chọn smooth_safe_level (mặc định tắt, dòng 42) nối thẳng các bậc để bỏ "vách đá" (Hạn chế #24). Trên trang, bảng mức an toàn đọc thẳng từ hàm getSafetyMarginMinPct nên không thể lệch với phép kiểm tra.
A29: Tiền cọc thuê (KHÔNG đưa vào model) | B29: 2 tháng tiền thuê | E29: Thực tiễn thị trường | F29: Chung cư thường cọc 2 tháng: https://wiki.batdongsan.com.vn/wiki/tien-coc-thue-nha-la-gi-cdk-109669 ; luật không quy định mức cọc (BLDS 2015 Đ328-330, Luật Nhà ở 2023): https://landager.com/vi/property-compliance/vietnam/national/security-deposits
A30: emergency_fund_months (quỹ dự phòng) | B30: 6 (user nhập) | E30: CHỐT 07/10 | F30: Số tháng sinh hoạt phí giữ lại, luôn ở kênh tiết kiệm. Tiền trả trước = tiết kiệm − phí mua 2,6% − quỹ dự phòng; đủ điều kiện khi tiết kiệm ≥ 20% giá + 2,6% + quỹ. Mức sàn = số tháng × sinh hoạt phí của chính tháng đó (tăng theo CPI). Áp dụng như nhau cho MUA và THUÊ. Mức 6 tháng là quy ước nhóm.
A31: investment_allocation_default (tỷ lệ 4 kênh) | B31: 100% tiết kiệm | E31: CHỐT 08/10 | F31: User tự đổi (tổng = 100%). Thiếu tiền: rút 4 kênh theo tỷ lệ, hết mới rút quỹ dự phòng. Dư tiền: trả khoản thiếu cũ → bù quỹ → chia theo tỷ lệ. Cân bằng lại mỗi 12 tháng.
A32: existing_debt_months (nợ đang trả còn bao nhiêu tháng) | B32: User nhập (trống = cả kỳ) | E32: CHỐT 07/10 | F32: Khoản nợ giữ nguyên số tiền, thôi trừ sau tháng này.
A33: Đo "cạn tiết kiệm" | B33: Chính: phải dùng quỹ dự phòng; phụ: hết sạch tiền | E33: CHỐT 08/10 | F33: Chính = tháng đầu phải rút quỹ dự phòng để trả chi phí thường xuyên (4 kênh đã hết). Phụ = tháng quỹ về 0; phần thiếu sau đó cộng dồn, không tính lãi, trừ vào tài sản ròng.
A34: Nhãn mức rủi ro (% kịch bản phải dùng quỹ) | B34: < 10% thấp / 10–25% vừa / > 25% cao | E34: CHỐT 08/10 (quy ước nhóm) | F34: Chỉ để đọc nhanh, số % gốc vẫn hiện. "Rủi ro thường xảy ra khi nào": so nhóm phải dùng quỹ với nhóm không dùng, nêu tối đa 2 biến có hiệu ứng ≥ 0,3 độ lệch chuẩn. Hạn chế #20. V5: khối kết luận dùng 3 nhãn theo kết quả kiểm tra an toàn: Comfortable (qua và còn dư từ 5 điểm % thu nhập trở lên so với mức an toàn ở tháng chặt nhất), Tight (qua nhưng dư dưới 5 điểm), Not safe (có tháng dưới mức an toàn). Chỉ là cách trình bày; qua hay không qua vẫn là is_safe. Nhãn rủi ro: < 10% low, 10–25% medium, > 25% high.
A35: Monte Carlo (thiết lập) | B35: 1.000 lần (bản nộp 10.000); độ nhạy 500 lần/dòng, 17 dòng; seed cố định 20260909 (mulberry32) | E35: CHỐT 08/10 | F35: σ và cách rút mẫu như các dòng trên. Khác repo Python: σ thu nhập 5,71 (chuỗi ĐBSH, thay 5,68 cả nước); mỗi kênh đầu tư rút riêng thay vì gộp một lợi suất danh mục; tăng giá nhà = cú sốc σ 4 điểm % cộng vào mọi năm của đường PA2; CPI không ngẫu nhiên. V3: thêm tùy chọn tương quan một nhân tố mc_shock_correlation (dòng 41, mặc định ρ = 0). Kiểm tra: σ = 0 thì mọi lần chạy trùng đường trung bình; ρ = 0 cho đúng kết quả V2.
A36: service_fee_vnd_per_m2 (đ/m²/tháng × diện tích căn, tăng theo CPI; cả MUA và THUÊ) | B36: 10000 | E36: CHỐT (09/10; mức nhóm chọn) | F36: Khung Hà Nội QĐ 33/2025/QĐ-UBND: nhà có thang máy 1.200–16.500 đ/m²/tháng (Thời báo Tài chính). Thực tế: Xuân Mai Complex (Hà Đông) ~5.000; Mandarin Garden (Cầu Giấy) ~14.000; Vinhomes Smart City 13.000–23.000 (VnExpress 22/4/2025). 10.000 là mức nhóm chọn giữa các mức này, dưới trần. Người sử dụng đóng (TVPL, Luật Nhà ở 2023, TT 05/2024/TT-BXD) và tin cho thuê thường chưa gồm phí này → áp cho cả hai bên. Độ nhạy 16.500 (trần khung). Hạn chế #22.
A37: owner_upkeep_pct (sửa chữa trong căn, % giá mua/năm, tăng theo CPI; chỉ bên MUA) | B37: 0 | E37: CHỐT (09/10): = 0 ở kết quả chính, chỉ độ nhạy | F37: Quy tắc "1% giá trị nhà mỗi năm" (Metrobank) chia đôi vì kết cấu và phần chung do quỹ bảo trì 2% và phí dịch vụ chi trả. Yếu nguồn nhất nên từ 09/10 nhóm KHÔNG đưa vào kết quả chính (mặc định 0); chỉ chạy dòng độ nhạy 1%/năm giá mua. Căn 6 tỷ với 1%: thêm ~5 triệu/tháng, % MUA giàu hơn sau 10 năm giảm 86% → 83% (hồ sơ thử 45 + 35 triệu, tiết kiệm 2,5 tỷ, 500 lượt). Hạn chế #23.
A38: fire_insurance_pct (bảo hiểm cháy nổ bắt buộc, % giá mua/năm, tăng theo CPI; chỉ bên MUA) | B38: 0.0005 | E38: CHỐT | F38: 0,05%/năm cho nhà có chữa cháy tự động: NĐ 67/2023/NĐ-CP và NĐ 105/2025/NĐ-CP (Luật Minh Khuê; LSVN). Luật tính trên chi phí xây lại, model tính trên giá mua nên là cận trên.
A39: selling_cost_pct (môi giới khi bán, % giá trị nhà năm đó; trừ khỏi Net worth MUA mỗi năm, kể cả năm 0) | B39: 0.015 | E39: CHỐT (09/10; mức nhóm chọn) | F39: Hoa hồng bán nhà, căn hộ 1–2% giá trị (wiki.batdongsan, 06/2023) → 1,5%. Độ nhạy 3,5% (= 1,5% môi giới + 2% thuế TNCN). Môi giới khi THUÊ = 0 (bên nào thuê môi giới thì bên đó trả; thường là chủ nhà).
A40: selling_tax_pct (thuế TNCN khi bán; trong code gộp vào selling_cost_pct, không có field riêng) | B40: 0 | E40: CHỐT | F40: Thuế suất 2% giá chuyển nhượng, Luật Thuế TNCN 2025 Điều 14 (TVPL); miễn khi bán nhà ở duy nhất đã sở hữu ≥ 183 ngày (Điều 4 khoản 2; NĐ 253/2026 Điều 19, Báo Pháp luật). Người dùng mục tiêu mua căn đầu tiên nên mặc định được miễn = 0%. Độ nhạy: selling_cost_pct = 3,5%. Hạn chế #17.
A41: mc_shock_correlation (ρ, tương quan một nhân tố giữa các cú sốc Monte Carlo) | B41: 0 | D41: per_path | E41: CHỐT (09/10; quy ước nhóm, chỉ stress test) | F41: Mặc định ρ = 0 (rút độc lập). ρ > 0: cú sốc mỗi biến = ρ·Z_chung + √(1 − ρ²)·Z_riêng, dấu đặt sao cho "xấu cùng lúc": lãi tham chiếu, lãi tiết kiệm, TPCP tăng; giá nhà, thu nhập, cổ phiếu giảm. σ từng biến giữ nguyên. Độ nhạy chạy ρ = 0,5. Không có nguồn cho ma trận tương quan nên chỉ dùng làm stress test. Hạn chế #7.
...

Sheet Kich_ban_do_nhay
A1: Kịch bản Boom / Stable / Downturn và độ nhạy (chốt 07/10/2026; cập nhật 09/10 theo V3–V5: thêm chi phí giữ nhà/bán và 5 dòng độ nhạy mới)
A2: Xanh dương = nhập tay; đen = công thức; xanh lá = lấy từ sheet khác. Kịch bản chỉ dời MỨC TRUNG BÌNH, σ giữ như sheet tổng hợp.
A4: Biến | B4: Boom | C4: Stable (base) | D4: Downturn | E4: Năm gốc / cách tính | F4: Nguồn
A5: Lãi tham chiếu | B5: =FIN_ASSUMPTIONS_tong_hop!B11-FIN_ASSUMPTIONS_tong_hop!C11 -> 0.0975 | C5: =FIN_ASSUMPTIONS_tong_hop!B11 -> 0.105 | D5: =FIN_ASSUMPTIONS_tong_hop!B11+FIN_ASSUMPTIONS_tong_hop!C11 -> 0.1125 | E5: Stable ± 1σ (0,75 điểm %) | F5: Lai_tham_chieu; Thanh Niên, Dân trí
A6: LTV | B6: 0.8 | C6: 0.8 | D6: 0.7 | E6: MB Vạn Phúc tối đa 80% (không dùng 100% của VCB cho Boom); Downturn 70% = ngân hàng siết | F6: Ảnh văn bản MB CN Vạn Phúc; VCB Nhà mới thành đạt (sheet Loan value)
A7: Tăng giá nhà: điểm đầu g0 | B7: ='Lạm phát giá mua bds - kan'!B5 -> 0.20431049 | C7: ='Lạm phát giá mua bds - kan'!B5 -> 0.20431049 | D7: ='Lạm phát giá mua bds - kan'!B4 -> 0.036422844 | E7: Boom/Stable: CAGR 2020–2025; Downturn: CAGR 2016–2020 (lặp lại giai đoạn đi ngang) | F7: CafeF, Cushman & Wakefield
A8: Tăng giá nhà: mức dài hạn g∞ | B8: =B21 -> 0.083817405 | C8: =B21 -> 0.083817405 | D8: =B21 -> 0.083817405 | E8: CPI TB 2016–2025 + tăng GDP thực/người TB 2016–2025 (ô B21) | F8: World Bank
A9: Tăng giá nhà: τ (năm) | B9: 6.5 | C9: 3.24 | D9: 3.24 | E9: Boom: nguội chậm gấp đôi (độ nhạy đã có); Stable: hiệu chỉnh CAGR 10 năm = 12,66% | F9: B5.1 plan
A10: Tăng giá thuê | B10: 0.1 | C10: 0.06 | D10: 0.03 | E10: Boom: mức trên "5–10% ở một số dự án"; Downturn ≈ CPI | F10: VnExpress 15/08/2025; Vietnambiz 14/04/2025
A11: Thu nhập | B11: =AVERAGE('Biến động thu nhập household (k'!D10:D12) -> 0.092875792 | C11: =FIN_ASSUMPTIONS_tong_hop!B21 -> 0.055620076 | D11: ='Inflation - kan'!$B$6 -> 0.030920093 | E11: Boom: TB 2022–2024 chuỗi ĐBSH; Downturn = CPI (thu nhập thực đứng yên) | F11: NSO KSMS 2024 tr. 283; World Bank CPI
A12: Sinh hoạt phí (CPI) | B12: ='Inflation - kan'!$B$6 -> 0.030920093 | C12: ='Inflation - kan'!$B$6 -> 0.030920093 | D12: ='Inflation - kan'!$B$6 -> 0.030920093 | E12: Giữ nguyên: σ 0,54%, 2016–2025 trong 1,83–3,62% | F12: World Bank CPI
A13: Tiết kiệm 6–12 tháng | B13: =AVERAGE('Lãi huy động (kan)'!E6:E7) -> 0.0585 | C13: =FIN_ASSUMPTIONS_tong_hop!B23 -> 0.065 | D13: ='Lãi huy động (kan)'!E8 -> 0.076 | E13: Đi cùng chiều lãi vay. Boom: TB 2020–2021; Downturn: 2022 | F13: FiinPro
A14: Trái phiếu TPCP 10 năm | B14: =AVERAGE('Return Bond (kan)'!E6:E7) -> 0.024 | C14: =FIN_ASSUMPTIONS_tong_hop!B25 -> 0.040218182 | D14: ='Return Bond (kan)'!E8 -> 0.0504 | E14: Boom: TB 2020–2021; Downturn: 2022 | F14: FiinPro
A15: Cổ phiếu (VN-Index) | B15: =FIN_ASSUMPTIONS_tong_hop!B24 -> 0.079904483 | C15: =FIN_ASSUMPTIONS_tong_hop!B24 -> 0.079904483 | D15: =FIN_ASSUMPTIONS_tong_hop!B24 -> 0.079904483 | E15: Giữ nguyên: không đi theo chu kỳ nhà (2025 nhà +26,7%, VNI +40,9%; 2022 nhà 0%, VNI −32,8%) | F15: investing.com
A16: Vàng (SJC) | B16: =FIN_ASSUMPTIONS_tong_hop!B26 -> 0.11115046 | C16: =FIN_ASSUMPTIONS_tong_hop!B26 -> 0.11115046 | D16: =FIN_ASSUMPTIONS_tong_hop!B26 -> 0.11115046 | E16: Giữ nguyên; base bỏ cú tăng 2025 | F16: FiinPro
A17: Chi phí giữ nhà / bán (V3) | B17: =C17 -> 10.000 đ/m²; bảo hiểm 0,05%; bán 1,5%; sửa chữa 0 | C17: 10.000 đ/m²; bảo hiểm 0,05%; bán 1,5%; sửa chữa 0 | D17: =C17 -> 10.000 đ/m²; bảo hiểm 0,05%; bán 1,5%; sửa chữa 0 | E17: Giữ nguyên ở cả ba: không đi theo chu kỳ thị trường; mức cao hơn chỉ chạy trong độ nhạy | F17: B4.1; FIN_ASSUMPTIONS_tong_hop dòng 36–40
A19: Ba nguyên tắc (chốt 07/10): (1) mỗi kịch bản giống một giai đoạn đã xảy ra trong dữ liệu 2016–2026, số nào cũng có năm gốc; (2) chỉ dời mức trung bình, σ giữ như sheet tổng hợp; (3) biến không đi theo chu kỳ nhà (CPI, cổ phiếu, vàng, chi phí giữ nhà) giữ nguyên ở cả ba. Kỳ hạn vay không đổi theo kịch bản.
A21: g∞ = CPI TB + tăng GDP thực/người TB (2016–2025) | B21: ='Inflation - kan'!$B$6+AVERAGE('GDP per capita - kan'!B3:K3) -> 0.083817405
A23: Đường tăng giá nhà theo kịch bản: g(t) = g∞ + (g0 − g∞)·e^(−(t−1)/τ), t = năm 1, 2, ... | I23: Tóm tắt
A24: Năm t | B24: g Boom | C24: g Stable | D24: g Downturn | E24: Hệ số Boom | F24: Hệ số Stable | G24: Hệ số Downturn | J24: Năm 1 | K24: Năm 5 | L24: Năm 10 | M24: CAGR 10 năm | N24: CAGR 30 năm | O24: Giá nhân sau 30 năm
A25: 1 | B25: =B$8+(B$7-B$8)*EXP(-($A25-1)/B$9) -> 0.20431049 | C25: =C$8+(C$7-C$8)*EXP(-($A25-1)/C$9) -> 0.20431049 | D25: =D$8+(D$7-D$8)*EXP(-($A25-1)/D$9) -> 0.036422844 | E25: =(1+B25) -> 1.2043105 | F25: =(1+C25) -> 1.2043105 | G25: =(1+D25) -> 1.0364228 | I25: Boom | J25: =B25 -> 0.20431049 | K25: =B29 -> 0.14893584 | L25: =B34 -> 0.11399129 | M25: =E34^(1/10)-1 -> 0.14981786 | N25: =E54^(1/30)-1 -> 0.11124554 | O25: =E54 -> 23.675598
A26: 2 | B26: =B$8+(B$7-B$8)*EXP(-($A26-1)/B$9) -> 0.18712864 | C26: =C$8+(C$7-C$8)*EXP(-($A26-1)/C$9) -> 0.17231279 | D26: =D$8+(D$7-D$8)*EXP(-($A26-1)/D$9) -> 0.04900877 | E26: =(1+B26)*E25 -> 1.4296715 | F26: =(1+C26)*F25 -> 1.4118286 | G26: =(1+D26)*G25 -> 1.0872167 | I26: Stable | J26: =C25 -> 0.20431049 | K26: =C29 -> 0.11887613 | L26: =C34 -> 0.091309246 | M26: =F34^(1/10)-1 -> 0.12656641 | N26: =F54^(1/30)-1 -> 0.098581098 | O26: =F54 -> 16.786636
A27: 3 | B27: =B$8+(B$7-B$8)*EXP(-($A27-1)/B$9) -> 0.17239687 | C27: =C$8+(C$7-C$8)*EXP(-($A27-1)/C$9) -> 0.14881228 | D27: =D$8+(D$7-D$8)*EXP(-($A27-1)/D$9) -> 0.058252423 | E27: =(1+B27)*E26 -> 1.6761424 | F27: =(1+C27)*F26 -> 1.621926 | G27: =(1+D27)*G26 -> 1.1505497 | I27: Downturn | J27: =D25 -> 0.036422844 | K27: =D29 -> 0.070027462 | L27: =D34 -> 0.080870576 | M27: =G34^(1/10)-1 -> 0.066692207 | N27: =G54^(1/30)-1 -> 0.077808887 | O27: =G54 -> 9.4678814
A28: 4 | B28: =B$8+(B$7-B$8)*EXP(-($A28-1)/B$9) -> 0.15976578 | C28: =C$8+(C$7-C$8)*EXP(-($A28-1)/C$9) -> 0.13155248 | D28: =D$8+(D$7-D$8)*EXP(-($A28-1)/D$9) -> 0.065041366 | E28: =(1+B28)*E27 -> 1.9439326 | F28: =(1+C28)*F27 -> 1.8352944 | G28: =(1+D28)*G27 -> 1.225383
A29: 5 | B29: =B$8+(B$7-B$8)*EXP(-($A29-1)/B$9) -> 0.14893584 | C29: =C$8+(C$7-C$8)*EXP(-($A29-1)/C$9) -> 0.11887613 | D29: =D$8+(D$7-D$8)*EXP(-($A29-1)/D$9) -> 0.070027462 | E29: =(1+B29)*E28 -> 2.2334538 | F29: =(1+C29)*F28 -> 2.0534671 | G29: =(1+D29)*G28 -> 1.3111934
A30: 6 | B30: =B$8+(B$7-B$8)*EXP(-($A30-1)/B$9) -> 0.13965021 | C30: =C$8+(C$7-C$8)*EXP(-($A30-1)/C$9) -> 0.10956606 | D30: =D$8+(D$7-D$8)*EXP(-($A30-1)/D$9) -> 0.073689469 | E30: =(1+B30)*E29 -> 2.5453561 | F30: =(1+C30)*F29 -> 2.2784574 | G30: =(1+D30)*G29 -> 1.4078146
A31: 7 | B31: =B$8+(B$7-B$8)*EXP(-($A31-1)/B$9) -> 0.13168867 | C31: =C$8+(C$7-C$8)*EXP(-($A31-1)/C$9) -> 0.10272834 | D31: =D$8+(D$7-D$8)*EXP(-($A31-1)/D$9) -> 0.076379006 | E31: =(1+B31)*E30 -> 2.8805506 | F31: =(1+C31)*F30 -> 2.5125195 | G31: =(1+D31)*G30 -> 1.5153421
A32: 8 | B32: =B$8+(B$7-B$8)*EXP(-($A32-1)/B$9) -> 0.12486241 | C32: =C$8+(C$7-C$8)*EXP(-($A32-1)/C$9) -> 0.097706424 | D32: =D$8+(D$7-D$8)*EXP(-($A32-1)/D$9) -> 0.07835432 | E32: =(1+B32)*E31 -> 3.2402231 | F32: =(1+C32)*F31 -> 2.7580088 | G32: =(1+D32)*G31 -> 1.6340757
A33: 9 | B33: =B$8+(B$7-B$8)*EXP(-($A33-1)/B$9) -> 0.11900956 | C33: =C$8+(C$7-C$8)*EXP(-($A33-1)/C$9) -> 0.094018107 | D33: =D$8+(D$7-D$8)*EXP(-($A33-1)/D$9) -> 0.079805077 | E33: =(1+B33)*E32 -> 3.6258406 | F33: =(1+C33)*F32 -> 3.0173116 | G33: =(1+D33)*G32 -> 1.7644832
A34: 10 | B34: =B$8+(B$7-B$8)*EXP(-($A34-1)/B$9) -> 0.11399129 | C34: =C$8+(C$7-C$8)*EXP(-($A34-1)/C$9) -> 0.091309246 | D34: =D$8+(D$7-D$8)*EXP(-($A34-1)/D$9) -> 0.080870576 | E34: =(1+B34)*E33 -> 4.0391549 | F34: =(1+C34)*F33 -> 3.29282 | G34: =(1+D34)*G33 -> 1.907178
A35: 11 | B35: =B$8+(B$7-B$8)*EXP(-($A35-1)/B$9) -> 0.10968862 | C35: =C$8+(C$7-C$8)*EXP(-($A35-1)/C$9) -> 0.08931974 | D35: =D$8+(D$7-D$8)*EXP(-($A35-1)/D$9) -> 0.081653125 | E35: =(1+B35)*E34 -> 4.4822042 | F35: =(1+C35)*F34 -> 3.5869339 | G35: =(1+D35)*G34 -> 2.062905
A36: 12 | B36: =B$8+(B$7-B$8)*EXP(-($A36-1)/B$9) -> 0.10599948 | C36: =C$8+(C$7-C$8)*EXP(-($A36-1)/C$9) -> 0.087858561 | D36: =D$8+(D$7-D$8)*EXP(-($A36-1)/D$9) -> 0.082227864 | E36: =(1+B36)*E35 -> 4.9573155 | F36: =(1+C36)*F35 -> 3.9020767 | G36: =(1+D36)*G35 -> 2.2325333
A37: 13 | B37: =B$8+(B$7-B$8)*EXP(-($A37-1)/B$9) -> 0.10283641 | C37: =C$8+(C$7-C$8)*EXP(-($A37-1)/C$9) -> 0.086785406 | D37: =D$8+(D$7-D$8)*EXP(-($A37-1)/D$9) -> 0.082649976 | E37: =(1+B37)*E36 -> 5.4671081 | F37: =(1+C37)*F36 -> 4.24072 | G37: =(1+D37)*G36 -> 2.4170521
A38: 14 | B38: =B$8+(B$7-B$8)*EXP(-($A38-1)/B$9) -> 0.10012437 | C38: =C$8+(C$7-C$8)*EXP(-($A38-1)/C$9) -> 0.085997235 | D38: =D$8+(D$7-D$8)*EXP(-($A38-1)/D$9) -> 0.082959995 | E38: =(1+B38)*E37 -> 6.0144988 | F38: =(1+C38)*F37 -> 4.6054102 | G38: =(1+D38)*G37 -> 2.6175707
A39: 15 | B39: =B$8+(B$7-B$8)*EXP(-($A39-1)/B$9) -> 0.097799061 | C39: =C$8+(C$7-C$8)*EXP(-($A39-1)/C$9) -> 0.085418367 | D39: =D$8+(D$7-D$8)*EXP(-($A39-1)/D$9) -> 0.083187685 | E39: =(1+B39)*E38 -> 6.6027111 | F39: =(1+C39)*F38 -> 4.9987969 | G39: =(1+D39)*G38 -> 2.8353204
... A54: 30 | B54: =B$8+(B$7-B$8)*EXP(-($A54-1)/B$9) -> 0.085208448 | C54: =C$8+(C$7-C$8)*EXP(-($A54-1)/C$9) -> 0.083833028 | D54: =D$8+(D$7-D$8)*EXP(-($A54-1)/D$9) -> 0.08381126 | E54: =(1+B54)*E53 -> 23.675598 | F54: =(1+C54)*F53 -> 16.786636 | G54: =(1+D54)*G53 -> 9.4678814
A57: Độ nhạy (B7.1): đổi từng biến một, các biến khác giữ Stable. 16 dòng + dòng gốc Stable = 17 dòng, mỗi dòng 500 lần
A58: Biến | B58: Các mức thử | C58: Stable | D58: Lý do | E58: Nguồn
A59: Tăng giá nhà: τ | B59: 1 / 3,24 / 6,5 | C59: 3,24 | D59: Nguội nhanh / base / nguội chậm gấp đôi | E59: B5.1
A60: Tăng giá nhà: PA1 | B60: 19%/năm cố định | C60: — | D60: Cận trên đối chiếu, không dùng làm kịch bản | E60: B5.1
...

Sheet Inflation - kan
B1: 2016 | C1: 2017 | D1: 2018 | E1: 2019 | F1: 2020 | G1: 2021 | H1: 2022 | I1: 2023 | J1: 2024 | K1: 2025
A2: Vietnam | B2: 0.026682482 | C2: 0.035202569 | D2: 0.035396281 | E2: 0.027958237 | F2: 0.032209344 | G2: 0.018347155 | H2: 0.031565075 | I2: 0.032528928 | J2: 0.036210927 | K2: 0.033099931
A4: https://data.worldbank.org/indicator/FP.CPI.TOTL.ZG?end=2025&locations=VN&start=2016&view=chart
A6: Mean 2016-2025 | B6: =AVERAGE(B2:K2) -> 0.030920093
A7: Std 2016-2025 | B7: =STDEV(B2:K2) -> 0.0053809923
A9: Sửa 02/10 (#22): đổi số % (2.67) sang phân số (0.0267) để mọi sheet cùng đơn vị. Ô tô vàng = đã sửa.

Sheet GDP per capita - kan
B1: 2016 | C1: 2017 | D1: 2018 | E1: 2019 | F1: 2020 | G1: 2021 | H1: 2022 | I1: 2023 | J1: 2024 | K1: 2025
A2: Vietnam | B2: 2735.0604 | C2: 2956.1099 | D2: 3222.31 | E2: 3440.9003 | F2: 3534.0395 | G2: 3704.1936 | H2: 4147.6978 | I2: 4322.8257 | J2: 4716.6599 | K2: 5065.9909 | L2: (USD)
B3: 0.05354271 | C3: 0.056178787 | D3: 0.062809583 | E3: 0.063246489 | F3: 0.019158143 | G3: 0.01666516 | H3: 0.07725699 | I3: 0.042761632 | J3: 0.063659749 | K3: 0.073693882 | L3: tăng trưởng (phân số)
A4: https://data.worldbank.org/indicator/NY.GDP.PCAP.KD.ZG?end=2025&locations=VN&start=2016
A6: Sửa 02/10 (#22): dòng 3 đổi sang phân số. Lưu ý: dòng 2 là mức USD, dòng 3 là tăng trưởng GDP/người theo giá cố định (NY.GDP.PCAP.KD.ZG).

Sheet Giá vàng SJC - kan
A1: Ngày | B1: Giá vàng SJC - Giá bán (D) | C1: Return | D1: Đơn vị : VND/lượng | F1: fiinpro
A2: 42398 | B2: 32890000
A3: 42429 | B3: 33590000 | C3: =B3/B2 -1 -> 0.021283065 | E3: Standard deviation | F3: =STDEV(C3:C130) -> 0.040777887
A4: 42460 | B4: 33340000 | C4: =B4/B3 -1 -> -0.0074426913 | E4: Mean | F4: =AVERAGE(C3:C130) -> 0.012411207
A5: 42489 | B5: 33800000 | C5: =B5/B4 -1 -> 0.013797241 | E5: CAGR (năm) | F5: =(B130/B2)^(12/(ROWS(B3:B130)))-1 -> 0.14877423
A6: 42521 | B6: 33350000 | C6: =B6/B5 -1 -> -0.013313609 | E6: Mean năm (=mean tháng×12) | F6: =F4*12 -> 0.14893449
A7: 42551 | B7: 35220000 | C7: =B7/B6 -1 -> 0.056071964 | E7: Std năm (=std tháng×√12) | F7: =F3*SQRT(12) -> 0.14125874
A8: 42580 | B8: 36423000 | C8: =B8/B7 -1 -> 0.034156729
A9: 42613 | B9: 36218000 | C9: =B9/B8 -1 -> -0.0056283118 | E9: Sửa 02/10 (#17): ô F5 cũ =GEOMEAN(1+C130)-1 chỉ lấy 1 ô (ra -2,9%) → thay bằng CAGR 01/2016-09/2026.
A10: 42643 | B10: 36133000 | C10: =B10/B9 -1 -> -0.0023468993 | E10: F3, F4 là số THEO THÁNG; model chạy theo năm nên dùng F6, F7.
A11: 42674 | B11: 35423000 | C11: =B11/B10 -1 -> -0.019649628 | E11: Cảnh báo: std tính theo năm dương lịch (Dec-to-Dec) ≈ 24,9% > F7 vì lợi suất vàng có quán tính; 2025 tăng 81,5% → nên chạy độ nhạy.
A12: 42704 | B12: 34878000 | C12: =B12/B11 -1 -> -0.015385484
A13: 42734 | B13: 35093000 | C13: =B13/B12 -1 -> 0.0061643443 | E13: Mean năm 02/2016–12/2024 (bỏ cú tăng 2025) — BASE từ 07/10 | F13: =AVERAGE(C3:C109)*12 -> 0.11115046
A14: 42761 | B14: 35593000 | C14: =B14/B13 -1 -> 0.014247856 | E14: Lý do: 2025 tăng 81,5% (gấp gần 7 lần TB các năm còn lại); 9 tháng đầu 2026 giảm ~5,5%. F6 (14,89%, cả chuỗi) giữ làm độ nhạy; σ vẫn dùng F7 (cả chuỗi) cho thận trọng.
A15: 42794 | B15: 35903000 | C15: =B15/B14 -1 -> 0.0087095777
A16: 42825 | B16: 35583000 | C16: =B16/B15 -1 -> -0.0089129042
A17: 42853 | B17: 36023000 | C17: =B17/B16 -1 -> 0.012365455
A18: 42886 | B18: 35698000 | C18: =B18/B17 -1 -> -0.0090220137
A19: 42916 | B19: 35618000 | C19: =B19/B18 -1 -> -0.0022410219
A20: 42947 | B20: 35713000 | C20: =B20/B19 -1 -> 0.0026671907
A21: 42978 | B21: 36193000 | C21: =B21/B20 -1 -> 0.013440484
A22: 43007 | B22: 36228000 | C22: =B22/B21 -1 -> 0.00096703782
A23: 43039 | B23: 36078000 | C23: =B23/B22 -1 -> -0.0041404439
A24: 43069 | B24: 36258000 | C24: =B24/B23 -1 -> 0.0049891901
A25: 43098 | B25: 36378000 | C25: =B25/B24 -1 -> 0.0033096144
A26: 43131 | B26: 36968000 | C26: =B26/B25 -1 -> 0.016218594
... A130: 46290 | B130: 144400000 | C130: =B130/B129 -1 -> -0.028917283

Sheet Return Bond (kan)
A1: STT | B1: Kỳ | C1: Ngày | D1: Lợi suất trái phiếu chính phủ 5 năm Đơn vị: % | E1: Lợi suất trái phiếu chính phủ 10 năm Đơn vị: % | G1: fiinpro
A2: 1 | B2: 2016 | C2: 42731 | D2: 0.056 | E2: 0.0638
A3: 2 | B3: 2017 | C3: 43095 | D3: 0.0435 | E3: 0.0519 | H3: 10 năm
A4: 3 | B4: 2018 | C4: 43462 | D4: 0.0456 | E4: 0.0513 | G4: Standard deviation | H4: =_xlfn.STDEV.S(E2:E12) -> 0.013650701
A5: 4 | B5: 2019 | C5: 43830 | D5: 0.0203 | E5: 0.0342 | G5: Mean | H5: =AVERAGE(E2:E12) -> 0.040218182
A6: 5 | B6: 2020 | C6: 44196 | D6: 0.0121 | E6: 0.0245 | G6: Mean 5 năm | H6: =AVERAGE(D2:D12) -> 0.032272727
A7: 6 | B7: 2021 | C7: 44561 | D7: 0.0088 | E7: 0.0235 | G7: Std 5 năm | H7: =STDEV(D2:D12) -> 0.016385487
A8: 7 | B8: 2022 | C8: 44925 | D8: 0.0493 | E8: 0.0504
A9: 8 | B9: 2023 | C9: 45289 | D9: 0.0172 | E9: 0.0239 | G9: Ghi chú 02/10 (#23): std ở đây là std của MỨC lợi suất cuối năm, không phải std lợi nhuận.
A10: 9 | B10: 2024 | C10: 45657 | D10: 0.0244 | E10: 0.0312 | G10: Dùng được khi giả định mua & giữ đến đáo hạn (lợi nhuận ≈ lợi suất lúc mua). Nguồn: FiinPro — ghi mã chuỗi + ngày tải.
A11: 10 | B11: 2025 | C11: 46022 | D11: 0.0339 | E11: 0.0419
A12: 11 | B12: 2026 | C12: 46290 | D12: 0.0439 | E12: 0.0458

Sheet VNIndex return - npp
A1: Tháng (đã sửa) | B1: VNINDEX | C1: VNI return | Q1: Thống kê tính lại (02/10)
A2: 46235 | B2: 1832.12 | C2: =B2/B3-1 -> 0.055502425
A3: 46204 | B3: 1735.78 | C3: =B3/B4-1 -> -0.066789963 | P3: Mean tháng | Q3: =AVERAGE(C2:C64) -> 0.0066587069
A4: 46174 | B4: 1860.01 | C4: =B4/B5-1 -> -0.0018674637 | P4: Std tháng | Q4: =STDEV(C2:C64) -> 0.055706198
A5: 46143 | B5: 1863.49 | C5: =B5/B6-1 -> 0.0050644518 | P5: Mean năm (×12) | Q5: =Q3*12 -> 0.079904483
A6: 46113 | B6: 1854.1 | C6: =B6/B7-1 -> 0.10726251 | D6: return vnindex | E6: 0.142 | G6: SUMMARY OUTPUT | P6: Std năm (×√12) | Q6: =Q4*SQRT(12) -> 0.19297193
A7: 46082 | B7: 1674.49 | C7: =B7/B8-1 -> -0.10947015 | P7: CAGR 05/2021-08/2026 | Q7: =(B2/B65)^(12/(ROWS(B2:B65)-1))-1 -> 0.063205086
A8: 46054 | B8: 1880.33 | C8: =B8/B9-1 -> 0.028042033 | G8: Regression Statistics
A9: 46023 | B9: 1829.04 | C9: =B9/B10-1 -> 0.024965116 | G9: Multiple R | H9: 622.139
A10: 45992 | B10: 1784.49 | C10: =B10/B11-1 -> 0.055293053 | G10: R Square | H10: 387.057 | P10: Sửa 02/10 (#18): cột A bị lỗi autodate — nhãn "Mmm-YY" bị hiểu thành ngày Mmm-DD/2026 (năm thật nằm ở ô ngày).
A11: 45962 | B11: 1690.99 | C11: =B11/B12-1 -> 0.03131156 | G11: Adjusted R Square | H11: 376.489 | P11: Đã đổi thành ngày 1 của tháng thật: tháng giữ nguyên, năm = 2000 + số ngày cũ. Chuỗi: 05/2021 → 08/2026, giảm dần.
A12: 45931 | B12: 1639.65 | C12: =B12/B13-1 -> -0.013269543 | G12: Standard Error | H12: 80.052 | P12: E6 = 14,2% (gõ tay) và khối hồi quy G6:O23 (lỗi định dạng số locale, VD Multiple R = 622.139) KHÔNG dùng; dùng Q5-Q7.
A13: 45901 | B13: 1661.7 | C13: =B13/B14-1 -> -0.012192295 | G13: Observations | H13: 60 | P13: Ô C65 báo lỗi chia 0 là lỗi CỐ Ý của team (xem comment) — giữ nguyên, không nằm trong vùng tính.
A14: 45870 | B14: 1682.21 | C14: =B14/B15-1 -> 0.11959242
A15: 45839 | B15: 1502.52 | C15: =B15/B16-1 -> 0.091892128 | G15: ANOVA
A16: 45809 | B16: 1376.07 | C16: =B16/B17-1 -> 0.032620441 | H16: df | I16: SS | J16: MS | K16: F | L16: Significance F
A17: 45778 | B17: 1332.6 | C17: =B17/B18-1 -> 0.08668352 | G17: Regression | H17: 1 | I17: 234.709 | J17: 234.709 | K17: 3.662.546.902 | L17: 1.12e-07
A18: 45748 | B18: 1226.3 | C18: =B18/B19-1 -> -0.06164394 | G18: Residual | H18: 58 | I18: 371.684 | J18: 6.408
A19: 45717 | B19: 1306.86 | C19: =B19/B20-1 -> 0.0011491083 | G19: Total | H19: 59 | I19: 606.393
A20: 45689 | B20: 1305.36 | C20: =B20/B21-1 -> 0.031864353
A21: 45658 | B21: 1265.05 | C21: =B21/B22-1 -> -0.0013656673 | H21: Coefficients | I21: Standard Error | J21: t Stat | K21: P-value | L21: Lower 95% | M21: Upper 95% | N21: Lower 95.0% | O21: Upper 95.0%
A22: 45627 | B22: 1266.78 | C22: =B22/B23-1 -> 0.013051197 | G22: Intercept | H22: -1.626 | I22: 10.451 | J22: -15.557 | K22: 125.219.955 | L22: -3.718 | M22: 4.661 | N22: -3.718 | O22: 4.661
A23: 45597 | B23: 1250.46 | C23: =B23/B24-1 -> -0.011087562 | G23: X Variable 1 | H23: 1.112.201 | I23: 183.777 | J23: 6.051.898 | K23: 0.0111901 | L23: 744.331 | M23: 1.480.071 | N23: 744.331 | O23: 1.480.071
A24: 45566 | B24: 1264.48 | C24: =B24/B25-1 -> -0.018215134
A25: 45536 | B25: 1287.94 | C25: =B25/B26-1 -> 0.0031701029
A26: 45505 | B26: 1283.87 | C26: =B26/B27-1 -> 0.025856765
A27: 45474 | B27: 1251.51 | C27: =B27/B28-1 -> 0.00497061
A28: 45444 | B28: 1245.32 | C28: =B28/B29-1 -> -0.01299813
A29: 45413 | B29: 1261.72 | C29: =B29/B30-1 -> 0.043157616
A30: 45383 | B30: 1209.52 | C30: =B30/B31-1 -> -0.058072254
A31: 45352 | B31: 1284.09 | C31: =B31/B32-1 -> 0.025033327
A32: 45323 | B32: 1252.73 | C32: =B32/B33-1 -> 0.075941974
A33: 45292 | B33: 1164.31 | C33: =B33/B34-1 -> 0.030426664
A34: 45261 | B34: 1129.93 | C34: =B34/B35-1 -> 0.032720061
A35: 45231 | B35: 1094.13 | C35: =B35/B36-1 -> 0.064132116
... A64: 44348 | B64: 1408.55 | C64: =B64/B65-1 -> 0.060615188
A65: 44317 | B65: 1328.05

Sheet Lãi huy động (kan)
A1: STT | B1: Kỳ | C1: Ngày | D1: LSHĐ_VND - Kỳ hạn < 1 tháng - Cao nhất (M) Đơn vị: % | E1: LSHĐ_VND - Kỳ hạn 6 - 12 tháng - Cao nhất (M) Đơn vị: % | F1: LSHĐ_VND - Kỳ hạn > 12 tháng - Cao nhất (M) Đơn vị: %
A2: 1 | B2: 2016 | C2: 42731 | D2: 0.01 | E2: 0.065 | F2: 0.072
A3: 2 | B3: 2017 | C3: 43095 | D3: 0.01 | E3: 0.065 | F3: 0.073 | H3: >12 tháng
A4: 3 | B4: 2018 | C4: 43462 | D4: 0.01 | E4: 0.065 | F4: 0.073 | H4: Standard deviation | I4: =STDEV(F2:F12) -> 0.0063000721
A5: 4 | B5: 2019 | C5: 43830 | D5: 0.008 | E5: 0.07 | F5: 0.075 | H5: Mean | I5: =AVERAGE(F2:F12) -> 0.070909091
A6: 5 | B6: 2020 | C6: 44196 | D6: 0.002 | E6: 0.06 | F6: 0.068 | H6: 6-12 tháng (chứa kỳ hạn 12T)
A7: 6 | B7: 2021 | C7: 44561 | D7: 0.002 | E7: 0.057 | F7: 0.065 | H7: 6-12 tháng: Std | I7: =STDEV(E2:E12) -> 0.0081608823
A8: 7 | B8: 2022 | C8: 44925 | D8: 0.006 | E8: 0.076 | F8: 0.074 | H8: 6-12 tháng: Mean | I8: =AVERAGE(E2:E12) -> 0.065
A9: 8 | B9: 2023 | C9: 45289 | D9: 0.002 | E9: 0.066 | F9: 0.081
A10: 9 | B10: 2024 | C10: 45657 | D10: 0.002 | E10: 0.052 | F10: 0.059 | H10: Ghi chú 02/10 (#20): cả 3 cột là mức CAO NHẤT thị trường → là CẬN TRÊN, không phải bình quân.
A11: 10 | B11: 2025 | C11: 46022 | D11: 0.002 | E11: 0.059 | F11: 0.064 | H11: Đối chiếu: DIV (27/01/2026) — NH dẫn đầu niêm yết 7,0-7,2%/năm kỳ hạn 12 tháng → khớp mức cao nhất 2026 ở đây.
A12: 11 | B12: 2026 | C12: 46290 | D12: 0.002 | E12: 0.08 | F12: 0.076 | H12: Nguồn: https://div.gov.vn/lai-suat-tiet-kiem-tang-trong-tam-kiem-soat-mt-bang-cho-vay-du-kien-tiep-tuc-on-dinh
H13: Kênh savings trong model dùng chuỗi 6-12 tháng (I7, I8).
A48: Biểu đồ (chart) lãi suất tiết kiệm (lãi suất tiền gửi/huy động)

Sheet Biến động thu nhập household (k
A1: Year | B1: Total | D1: Tăng trưởng/năm (quy đổi) | G1: Thống kê đúng (02/10)
A2: 2010 | B2: 1580400 | G2: Mean 2019-2024 (hằng năm) | H2: =AVERAGE(D7:D12) -> 0.055620076
A3: 2012 | B3: 2350600 | C3: =B3/B2 -1 -> 0.48734498 | D3: =(B3/B2)^(1/(A3-A2))-1 -> 0.21956754 | G3: Std 2019-2024 (hằng năm) | H3: =STDEV(D7:D12) -> 0.057109401
A4: 2014 | B4: 3264900 | C4: =B4/B3 -1 -> 0.38896452 | D4: =(B4/B3)^(1/(A4-A3))-1 -> 0.17854339 | G4: Mean 2010-2024 (quy đổi) | H4: =AVERAGE(D3:D12) -> 0.093131573
A5: 2016 | B5: 3883300 | C5: =B5/B4 -1 -> 0.18940856 | D5: =(B5/B4)^(1/(A5-A4))-1 -> 0.090600091 | G5: Std 2010-2024 (quy đổi) | H5: =STDEV(D3:D12) -> 0.073246827
A6: 2018 | B6: 4775000 | C6: =B6/B5 -1 -> 0.22962429 | D6: =(B6/B5)^(1/(A6-A5))-1 -> 0.10888425 | G6: CAGR 2010-2024 | H6: =(B12/B2)^(1/(A12-A2))-1 -> 0.10698986
A7: 2019 | B7: 5190700 | C7: =B7/B6 -1 -> 0.087057592 | D7: =(B7/B6)^(1/(A7-A6))-1 -> 0.087057592 | E7: đồng bằng sông hồng
A8: 2020 | B8: 5084100 | C8: =B8/B7 -1 -> -0.020536729 | D8: =(B8/B7)^(1/(A8-A7))-1 -> -0.020536729 | E8: =STDEV(C3:C12) -> 0.16562537 | G8: Sửa 02/10 (#15): cột C cũ chia thẳng giữa các dòng, nên tăng trưởng 2 NĂM (VD +48,7% 2010→2012) bị coi như 1 năm.
A9: 2021 | B9: 5026000 | C9: =B9/B8 -1 -> -0.011427785 | D9: =(B9/B8)^(1/(A9-A8))-1 -> -0.011427785 | E9: =AVERAGE(C3:C12) -> 0.16290628 | G9: Cột D quy về mỗi năm: (B_t/B_t-1)^(1/số năm)-1. Model dùng H2/H3 (giai đoạn đo hằng năm, n=6).
A10: 2022 | B10: 5586500 | C10: =B10/B9 -1 -> 0.1115201 | D10: =(B10/B9)^(1/(A10-A9))-1 -> 0.1115201 | G10: Đã xác nhận (07/10): chuỗi Đồng bằng sông Hồng, NSO KSMS 2024 trang 283. Đối chiếu: repo dùng NSO cả nước 2019-2024 → 4,87% ± 5,68%.
A11: 2023 | B11: 5980600 | C11: =B11/B10 -1 -> 0.070545064 | D11: =(B11/B10)^(1/(A11-A10))-1 -> 0.070545064 | G11: Danh nghĩa (có lạm phát), thu nhập đầu người/tháng. Có 2 năm COVID (2020-2021).
A12: 2024 | B12: 6558100 | C12: =B12/B11 -1 -> 0.096562218 | D12: =(B12/B11)^(1/(A12-A11))-1 -> 0.096562218
A14: https://www.nso.gov.vn/wp-content/uploads/2026/03/Sach-Khao-sat-muc-song-dan-cu-2024.pdf

Sheet Lạm phát giá mua bds - kan
A1: Year | B1: 2016 | C1: 2017 | D1: 2018 | E1: 2019 | F1: 2020 | G1: 2021 | H1: 2022 | I1: 2023 | J1: 2024 | K1: 2025
A2: Avg. primary price (USD/m², sơ cấp) | B2: 1300 | C2: 1200 | D2: 1250 | E2: 1400 | F2: 1500 | G2: 1900 | H2: 1900 | I2: 2200 | J2: 3000 | K2: 3800
A3: CAGR 2016-2025 | B3: =(K2/B2)^(1/9) -1 -> 0.12657479
A4: CAGR 2016-2020 | B4: =(F2/B2)^(1/4) -1 -> 0.036422844
A5: CAGR 2020- | B5: =(K2/F2)^(1/5)-1 -> 0.20431049
A7: https://cafef.vn/nhin-lai-10-nam-bds-ha-noi-gia-can-ho-tang-gan-300-thi-truong-chuan-bi-da-cuc-hoa-18826042315173533.chn
A8: https://cloud.comm.cushmanwakefield.com/Hanoi_realestate_market_review?
A10: Tăng trưởng YoY | C10: =C2/B2-1 -> -0.076923077 | D10: =D2/C2-1 -> 0.041666667 | E10: =E2/D2-1 -> 0.12 | F10: =F2/E2-1 -> 0.071428571 | G10: =G2/F2-1 -> 0.26666667 | H10: =H2/G2-1 -> 0 | I10: =I2/H2-1 -> 0.15789474 | J10: =J2/I2-1 -> 0.36363636 | K10: =K2/J2-1 -> 0.26666667
A11: Std YoY 2017-2025 | B11: =STDEV(C10:K10) -> 0.14299609
A13: Sửa 02/10 (#24): ghi đơn vị (USD/m², giá SƠ CẤP bình quân Hà Nội — theo bài CafeF/C&W; nhóm kiểm tra lại đơn vị trong bài gốc).
A14: Std YoY ~14% là dao động TỪNG NĂM. Model rút tăng giá 1 lần/đường (per_path) nên σ dùng là 4% (≈ bất định của mức TB 30 năm, 14%/√30 ≈ 2,6%).
A15: Đối chiếu thị trường thứ cấp: Global Property Guide Q2/2026 +13%/năm (https://www.globalpropertyguide.com/asia/vietnam/price-history).

Sheet Loan value - npp
A1: Tên ngân hàng | B1: Gói cho vay | C1: Loan value | D1: Thời hạn cho vay | E1: Ghi chú (02/10)
A2: VCB | B2: Vay mua nhà ở đất ở | C2: 1 | E2: VCB: 100% (gói Vay mua nhà ở đất ở)
A3: VCB | B3: Nhà mới thành đạt | C3: 0.7 | D3: 40 năm | E3: VCB: 70% → dùng cho kịch bản Downturn (worst case) | G3: Best case | H3: 1
A4: VCB | B4: Vay mua nhà dự án | C4: 1 | D4: 30 năm | E4: VCB: 100% (gói nhà dự án) → cùng BIDV, Vietinbank làm căn cứ Boom | G4: Base case | H4: 0.8
A5: BIDV | B5: Vay nhu cầu nhà ở | C5: 1 | D5: 30 năm | G5: Worst case | H5: 0.7
A6: Agribank | B6: Vay mua nhà ở cho người trẻ tuổi | D6: 40 năm | E6: "5 tỉ" là HẠN MỨC vay, không phải tỷ lệ LTV → đã chuyển khỏi cột Loan value; LTV gói này cần tra lại.
A7: Vietinbank | B7: Cho vay nhận quyền sử dụng đất, mua, xây dựng, sửa chữa nhà và/hoặc công trình xây dựng | C7: 1 | D7: 35 năm
A8: MB BANK | B8: Mua nhà đất thổ cư cho người trẻ | C8: 0.8 | D8: 35 năm | E8: Gói "người trẻ" 35 năm khác gói Vạn Phúc → không ghép vào bộ tham số Vạn Phúc
A9: MB BANK – CN Vạn Phúc | B9: Vay mua nhà đất, chung cư (văn bản CN Vạn Phúc) | C9: 0.8 | D9: 30 năm (360 tháng) | E9: Nguồn: ảnh văn bản gốc MB CN Vạn Phúc (docs/assets/mb-bank-rate-sheet.png) — BASE CASE 80%

Sheet Lãi suất vay nhà - npp
A1: Thời gian | B1: Ngân hàng | C1: Lãi suất | D1: Nguồn | E1: Loại lãi | F1: Ghi chú (02/10)
A2: Q3/2026 | B2: BIDV | C2: 0.1 | D2: Link | E2: Chưa xác định | F2: Link là gói ưu đãi "Ngôi nhà đầu tiên" → kiểm tra 10% là lãi ưu đãi hay sau ưu đãi
B3: VCB | C3: 0.052 | D3: Link | E3: Chưa xác định | F3: Link là gói Nhà mới thành đạt → nhiều khả năng lãi ưu đãi; kiểm tra kỳ hạn cố định
B4: Agri | C4: 0.0852 | D4: Link | E4: Chưa xác định | F4: Kiểm tra kỳ hạn cố định của 8,52%
A5: Q2/2026 | B5: BIDV | D5: Link
B6: VCB | D6: Link
B7: Agri | D7: Link
D8: Link
A10: Q3/2026 | B10: MB – CN Vạn Phúc | C10: 0.077 | D10: Ảnh văn bản gốc | E10: Ưu đãi cố định 6 tháng
A11: Q3/2026 | B11: MB – CN Vạn Phúc | C11: 0.083 | D11: Ảnh văn bản gốc | E11: Ưu đãi cố định 12 tháng
A12: Q3/2026 | B12: MB – CN Vạn Phúc | C12: 0.085 | D12: Ảnh văn bản gốc | E12: Ưu đãi cố định 18 tháng
A13: Q3/2026 | B13: MB – CN Vạn Phúc | C13: 0.09 | D13: Ảnh văn bản gốc | E13: Ưu đãi cố định 24 tháng
A15: MB sau ưu đãi | B15: Lãi tham chiếu + 1,5% (năm đầu sau ưu đãi), + 3,5% (các năm sau); điều chỉnh 3 tháng/lần. Lãi tham chiếu: xem sheet Lai_tham_chieu
A17: Sửa 02/10 (#21): thêm 4 mức ưu đãi MB (A10:E13) và cột Loại lãi để không trộn lãi ưu đãi với lãi thả nổi.

Sheet Lai_tham_chieu
A1: Phương án | B1: Giá trị (%/năm) | C1: Lãi thả nổi năm đầu sau ưu đãi | D1: Từ năm sau | E1: Nguồn / trạng thái | F1: Cách tính
A2: CHỐT (08/10) – ngoại suy từ lãi thả nổi thị trường | B2: 0.105 | C2: =B2+$B$7 -> 0.12 | D2: =B2+$B$8 -> 0.14 | E2: Thanh Niên 25/08/2026: https://thanhnien.vn/nguoi-vay-mua-nha-dang-chiu-lai-suat-bao-nhieu-185260825101722042.htm ; Dân trí 24/08/2026: https://dantri.com.vn/kinh-doanh/lai-suat-tha-noi-tren-14nam-ngan-hang-giam-cho-vay-mua-nha-20260823171410442.htm | F2: Lãi thả nổi thị trường 13–15%/năm − biên độ MB 3,5% = 9,5–11,5%; điểm giữa 10,5%. Độ nhạy 9,5–11,5%
A3: Đối chiếu – VCB lãi cho vay bình quân 06/2026 | B3: 0.075 | C3: =B3+$B$7 -> 0.09 | D3: =B3+$B$8 -> 0.11 | E3: https://www.vietcombank.com.vn/-/media/Project/VCB-Sites/VCB/Tin-tuc/2026/Vietcombank/Vietcombank_202607/Vietcombank_20260721/20260729_Thong-bao-lai-suat-2026-thang-6.pdf | F3: Lãi cho vay bình quân MỌI khoản vay, không phải lãi tham chiếu vay mua nhà
A4: Đối chiếu – NHNN lãi cho vay mới bình quân 11/2025 | B4: 0.0696 | C4: =B4+$B$7 -> 0.0846 | D4: =B4+$B$8 -> 0.1046 | E4: DIV 27/01/2026: https://div.gov.vn/lai-suat-tiet-kiem-tang-trong-tam-kiem-soat-mt-bang-cho-vay-du-kien-tiep-tuc-on-dinh | F4: Lãi cho vay MỌI mục đích, chỉ đối chiếu
A7: Biên độ năm đầu sau ưu đãi (MB) | B7: 0.015
A8: Biên độ các năm sau (MB) | B8: 0.035
A9: Mặt bằng lãi thả nổi thị trường 08/2026 | B9: 12–15%/năm (Thanh Niên, Dân trí)
A11: TRẠNG THÁI: CHỐT 10,5% (nhóm quyết 08/10; số ngoại suy). Văn bản MB CN Vạn Phúc không ghi giá trị lãi tham chiếu nên vẫn nên xác nhận với chuyên viên MB (Hạn chế #5).
A12: 10,5% → thả nổi 12% năm đầu sau ưu đãi, 14% các năm sau; nằm trong mặt bằng 12–15% tháng 8/2026. Monte Carlo rút σ = 0,75 điểm % quanh 10,5%.

Sheet Doi_chieu_index_html
A1: Đối chiếu bộ số trong Excel với FINAL PRODUCT V5 (index.html)
A2: Xanh dương = số gõ tay từ index.html (FIN_ASSUMPTIONS, MC_SETTINGS, SCENARIOS); xanh lá = lấy từ sheet khác; đen = công thức. Số trong code làm tròn 2 chữ số nên sai số cho phép 0,0051.
A3: Số dòng LỆCH: | B3: =COUNTIF(F6:F53,"LỆCH")+COUNTIF(F58:F70,"LỆCH") -> 0
A4: (đếm cả hai bảng; cột "Giá trị trong Excel" của bảng 1 là công thức nối từ các sheet khác)
A5: Tham số (key trong code) | B5: Đơn vị trong code | C5: Giá trị trong Excel (đổi sang đơn vị code) | D5: Giá trị trong index.html V5 | E5: Sai số cho phép | F5: Kết quả | G5: Ô nguồn trong Excel
A6: interest_rate_promo_pct — 6 tháng | B6: % | C6: =FIN_ASSUMPTIONS_tong_hop!B5*100 -> 7.7 | D6: 7.7 | E6: 0.0001 | F6: =IF(ABS(C6-D6)<=E6,"KHỚP","LỆCH") -> KHỚP | G6: tong_hop!B5
A7: interest_rate_promo_pct — 12 tháng | B7: % | C7: =FIN_ASSUMPTIONS_tong_hop!B6*100 -> 8.3 | D7: 8.3 | E7: 0.0001 | F7: =IF(ABS(C7-D7)<=E7,"KHỚP","LỆCH") -> KHỚP | G7: tong_hop!B6
A8: interest_rate_promo_pct — 18 tháng | B8: % | C8: =FIN_ASSUMPTIONS_tong_hop!B7*100 -> 8.5 | D8: 8.5 | E8: 0.0001 | F8: =IF(ABS(C8-D8)<=E8,"KHỚP","LỆCH") -> KHỚP | G8: tong_hop!B7
A9: interest_rate_promo_pct — 24 tháng | B9: % | C9: =FIN_ASSUMPTIONS_tong_hop!B8*100 -> 9 | D9: 9 | E9: 0.0001 | F9: =IF(ABS(C9-D9)<=E9,"KHỚP","LỆCH") -> KHỚP | G9: tong_hop!B8
A10: interest_rate_float_ref_pct | B10: % | C10: =FIN_ASSUMPTIONS_tong_hop!B11*100 -> 10.5 | D10: 10.5 | E10: 0.0001 | F10: =IF(ABS(C10-D10)<=E10,"KHỚP","LỆCH") -> KHỚP | G10: tong_hop!B11
A11: float_rate_margin_year1_pct | B11: % | C11: =FIN_ASSUMPTIONS_tong_hop!B9*100 -> 1.5 | D11: 1.5 | E11: 0.0001 | F11: =IF(ABS(C11-D11)<=E11,"KHỚP","LỆCH") -> KHỚP | G11: tong_hop!B9
A12: float_rate_margin_from_year2_pct | B12: % | C12: =FIN_ASSUMPTIONS_tong_hop!B10*100 -> 3.5 | D12: 3.5 | E12: 0.0001 | F12: =IF(ABS(C12-D12)<=E12,"KHỚP","LỆCH") -> KHỚP | G12: tong_hop!B10
A13: grace_period_months | B13: tháng | C13: =FIN_ASSUMPTIONS_tong_hop!B13 -> 24 | D13: 24 | E13: 0 | F13: =IF(ABS(C13-D13)<=E13,"KHỚP","LỆCH") -> KHỚP | G13: tong_hop!B13
A14: max_loan_to_value_pct (Stable) | B14: % | C14: =Kich_ban_do_nhay!C6*100 -> 80 | D14: 80 | E14: 0.0001 | F14: =IF(ABS(C14-D14)<=E14,"KHỚP","LỆCH") -> KHỚP | G14: Kich_ban!C6
A15: max_borrower_age | B15: tuổi | C15: =FIN_ASSUMPTIONS_tong_hop!B17 -> 70 | D15: 70 | E15: 0 | F15: =IF(ABS(C15-D15)<=E15,"KHỚP","LỆCH") -> KHỚP | G15: tong_hop!B17
A16: max_term_by_bank_months | B16: tháng | C16: =FIN_ASSUMPTIONS_tong_hop!B16 -> 360 | D16: 360 | E16: 0 | F16: =IF(ABS(C16-D16)<=E16,"KHỚP","LỆCH") -> KHỚP | G16: tong_hop!B16
A17: buy_closing_costs_pct | B17: % | C17: =FIN_ASSUMPTIONS_tong_hop!B18*100 -> 2.6 | D17: 2.6 | E17: 0.0001 | F17: =IF(ABS(C17-D17)<=E17,"KHỚP","LỆCH") -> KHỚP | G17: tong_hop!B18
A18: investment_channels.savings.return_pct | B18: % | C18: =FIN_ASSUMPTIONS_tong_hop!B23*100 -> 6.5 | D18: 6.5 | E18: 0.0051 | F18: =IF(ABS(C18-D18)<=E18,"KHỚP","LỆCH") -> KHỚP | G18: tong_hop!B23
A19: investment_channels.bonds.return_pct | B19: % | C19: =FIN_ASSUMPTIONS_tong_hop!B25*100 -> 4.0218182 | D19: 4.02 | E19: 0.0051 | F19: =IF(ABS(C19-D19)<=E19,"KHỚP","LỆCH") -> KHỚP | G19: tong_hop!B25
A20: investment_channels.gold.return_pct | B20: % | C20: =FIN_ASSUMPTIONS_tong_hop!B26*100 -> 11.115046 | D20: 11.12 | E20: 0.0051 | F20: =IF(ABS(C20-D20)<=E20,"KHỚP","LỆCH") -> KHỚP | G20: tong_hop!B26
A21: investment_channels.stocks.return_pct | B21: % | C21: =FIN_ASSUMPTIONS_tong_hop!B24*100 -> 7.9904483 | D21: 7.99 | E21: 0.0051 | F21: =IF(ABS(C21-D21)<=E21,"KHỚP","LỆCH") -> KHỚP | G21: tong_hop!B24
A22: property_appreciation_start_pct | B22: % | C22: =Kich_ban_do_nhay!C7*100 -> 20.431049 | D22: 20.43 | E22: 0.0051 | F22: =IF(ABS(C22-D22)<=E22,"KHỚP","LỆCH") -> KHỚP | G22: Kich_ban!C7
A23: property_appreciation_longrun_pct | B23: % | C23: =Kich_ban_do_nhay!C8*100 -> 8.3817405 | D23: 8.38 | E23: 0.0051 | F23: =IF(ABS(C23-D23)<=E23,"KHỚP","LỆCH") -> KHỚP | G23: Kich_ban!C8
A24: property_appreciation_tau_years | B24: năm | C24: =Kich_ban_do_nhay!C9 -> 3.24 | D24: 3.24 | E24: 0.0001 | F24: =IF(ABS(C24-D24)<=E24,"KHỚP","LỆCH") -> KHỚP | G24: Kich_ban!C9
A25: income_annual_growth_pct | B25: % | C25: =FIN_ASSUMPTIONS_tong_hop!B21*100 -> 5.5620076 | D25: 5.56 | E25: 0.0051 | F25: =IF(ABS(C25-D25)<=E25,"KHỚP","LỆCH") -> KHỚP | G25: tong_hop!B21
A26: living_cost_annual_growth_pct | B26: % | C26: =FIN_ASSUMPTIONS_tong_hop!B22*100 -> 3.0920093 | D26: 3.09 | E26: 0.0051 | F26: =IF(ABS(C26-D26)<=E26,"KHỚP","LỆCH") -> KHỚP | G26: tong_hop!B22
A27: rent_annual_growth_pct | B27: % | C27: =Kich_ban_do_nhay!C10*100 -> 6 | D27: 6 | E27: 0.0001 | F27: =IF(ABS(C27-D27)<=E27,"KHỚP","LỆCH") -> KHỚP | G27: Kich_ban!C10
A28: service_fee_vnd_per_m2 | B28: đ/m²/tháng | C28: =FIN_ASSUMPTIONS_tong_hop!B36 -> 10000 | D28: 10000 | E28: 0 | F28: =IF(ABS(C28-D28)<=E28,"KHỚP","LỆCH") -> KHỚP | G28: tong_hop!B36
A29: owner_upkeep_pct | B29: % | C29: =FIN_ASSUMPTIONS_tong_hop!B37*100 -> 0 | D29: 0 | E29: 0.0001 | F29: =IF(ABS(C29-D29)<=E29,"KHỚP","LỆCH") -> KHỚP | G29: tong_hop!B37
A30: fire_insurance_pct | B30: % | C30: =FIN_ASSUMPTIONS_tong_hop!B38*100 -> 0.05 | D30: 0.05 | E30: 0.0001 | F30: =IF(ABS(C30-D30)<=E30,"KHỚP","LỆCH") -> KHỚP | G30: tong_hop!B38
A31: selling_cost_pct | B31: % | C31: =FIN_ASSUMPTIONS_tong_hop!B39*100 -> 1.5 | D31: 1.5 | E31: 0.0001 | F31: =IF(ABS(C31-D31)<=E31,"KHỚP","LỆCH") -> KHỚP | G31: tong_hop!B39
A32: mc_shock_correlation | B32: ρ | C32: =FIN_ASSUMPTIONS_tong_hop!B41 -> 0 | D32: 0 | E32: 0.0001 | F32: =IF(ABS(C32-D32)<=E32,"KHỚP","LỆCH") -> KHỚP | G32: tong_hop!B41
A33: MC_SETTINGS.sigma.float_ref | B33: điểm % | C33: =FIN_ASSUMPTIONS_tong_hop!C11*100 -> 0.75 | D33: 0.75 | E33: 0.0001 | F33: =IF(ABS(C33-D33)<=E33,"KHỚP","LỆCH") -> KHỚP | G33: tong_hop!C11
A34: MC_SETTINGS.sigma.property | B34: điểm % | C34: =FIN_ASSUMPTIONS_tong_hop!C19*100 -> 4 | D34: 4 | E34: 0.0001 | F34: =IF(ABS(C34-D34)<=E34,"KHỚP","LỆCH") -> KHỚP | G34: tong_hop!C19
A35: MC_SETTINGS.sigma.rent | B35: điểm % | C35: =FIN_ASSUMPTIONS_tong_hop!C20*100 -> 1.25 | D35: 1.25 | E35: 0.0001 | F35: =IF(ABS(C35-D35)<=E35,"KHỚP","LỆCH") -> KHỚP | G35: tong_hop!C20
A36: MC_SETTINGS.sigma.income | B36: điểm % | C36: =FIN_ASSUMPTIONS_tong_hop!C21*100 -> 5.7109401 | D36: 5.71 | E36: 0.0051 | F36: =IF(ABS(C36-D36)<=E36,"KHỚP","LỆCH") -> KHỚP | G36: tong_hop!C21
A37: MC_SETTINGS.channel_sigma.savings | B37: điểm % | C37: =FIN_ASSUMPTIONS_tong_hop!C23*100 -> 0.81608823 | D37: 0.82 | E37: 0.0051 | F37: =IF(ABS(C37-D37)<=E37,"KHỚP","LỆCH") -> KHỚP | G37: tong_hop!C23
A38: MC_SETTINGS.channel_sigma.bonds | B38: điểm % | C38: =FIN_ASSUMPTIONS_tong_hop!C25*100 -> 1.3650701 | D38: 1.37 | E38: 0.0051 | F38: =IF(ABS(C38-D38)<=E38,"KHỚP","LỆCH") -> KHỚP | G38: tong_hop!C25
A39: MC_SETTINGS.channel_sigma.gold | B39: điểm % | C39: =FIN_ASSUMPTIONS_tong_hop!C26*100 -> 14.125874 | D39: 14.13 | E39: 0.0051 | F39: =IF(ABS(C39-D39)<=E39,"KHỚP","LỆCH") -> KHỚP | G39: tong_hop!C26
A40: MC_SETTINGS.channel_sigma.stocks | B40: điểm % | C40: =FIN_ASSUMPTIONS_tong_hop!C24*100 -> 19.297193 | D40: 19.3 | E40: 0.0051 | F40: =IF(ABS(C40-D40)<=E40,"KHỚP","LỆCH") -> KHỚP | G40: tong_hop!C24
...

Sheet Nhat_ky_v6
A1: Nhật ký sửa v4 → v6 (09/10/2026, khớp Final Plan v5 và FINAL PRODUCT V5)
A3: Vị trí | B3: Trước (v4) | C3: Sau (v6) | D3: Căn cứ
A4: FIN_ASSUMPTIONS_tong_hop!A1 | B4: FIN_ASSUMPTIONS — bộ số sau khi sửa (02/10/2026) | C4: FIN_ASSUMPTIONS — bộ số sau khi sửa (09/10/2026, khớp Final Plan v5 và FINAL PRODUCT V5) | D4: Đồng bộ ngày và phiên bản với plan v5
A5: FIN_ASSUMPTIONS_tong_hop!F18 | B5: "MVP: chỉ dùng trong kiểm tra minDownPayment…" | C5: Ghi rõ dùng ở B4 và dpLimit Plan B; thêm lưu ý căn bán lại ~0,56% | D5: Plan v5 B3, B4, B2.1 và mục "Bổ sung" cuối Hạn chế
A6: FIN_ASSUMPTIONS_tong_hop!E20:F20 | B6: ĐỀ XUẤT | VnExpress 08/2025: 5-10% một số dự án, 10-15% nhiều chung cư; repo: đi… | C6: CHỐT (09/10) + giải thích vì sao 6%, σ 1,25 | D6: Plan v5 B3 mục "Tăng giá thuê: vì sao base 6%/năm"; câu hỏi mở #4 đã chốt 09/10
A7: FIN_ASSUMPTIONS_tong_hop!F28 | B7: (không nhắc smooth_safe_level) | C7: Thêm ghi chú V3 smooth_safe_level | D7: Plan v5 B3 hàng safety_margin_min_pct; code getSafetyMarginMinPctSmooth
A8: FIN_ASSUMPTIONS_tong_hop!F34 | B8: (chỉ nhãn rủi ro) | C8: Thêm định nghĩa Comfortable / Tight / Not safe (ngưỡng 5 điểm %) | D8: Plan v5 B9 mục A.1; code TIGHT_BELOW_POINTS = 0.05
A9: FIN_ASSUMPTIONS_tong_hop!B35,F35 | B9: 1.000 lần (bản nộp 10.000); độ nhạy 500 lần/dòng; seed cố định | C9: 1.000 lần (bản nộp 10.000); độ nhạy 500 lần/dòng, 17 dòng; seed cố định 20260909 (mulberry32) | D9: Plan v5 B8 và B7.1 (17 dòng độ nhạy); code MC_SETTINGS.seed = 20260909
A10: FIN_ASSUMPTIONS_tong_hop!A36:F42 | B10: (chưa có) | C10: 7 dòng mới: phí dịch vụ 10.000 đ/m²; sửa chữa 0; bảo hiểm 0,05%; chi phí bán 1,5%; thuế TNCN 0%; ρ = 0; smooth_safe_level tắt | D10: Plan v5 B3 bảng "Chi chí vận hành và bán (V3)", B4.1, B7.1, B8; code FIN_ASSUMPTIONS
A11: Kich_ban_do_nhay!A1 | B11: Kịch bản Boom / Stable / Downturn và độ nhạy (chốt 07/10/2026) | C11: Kịch bản Boom / Stable / Downturn và độ nhạy (chốt 07/10/2026; cập nhật 09/10 theo V3–V5: thêm chi phí giữ nhà/bán và 5 dòng độ nhạy mới) | D11: Plan v5 B7, B7.1
A12: Kich_ban_do_nhay!A17:F17, A19 | B12: (chưa có) | C12: Thêm dòng chi phí giữ nhà/bán giữ nguyên ở 3 kịch bản (giá trị khớp tổng hợp dòng 36–40, được kiểm ở sheet Doi_chieu_index_html) và ghi 3 nguyên tắc kịch bản | D12: Plan v5 B7
A13: Kich_ban_do_nhay!A66:E70 | B13: (chưa có) | C13: 5 dòng độ nhạy mới: phí dịch vụ, sửa chữa, chi phí bán, ρ, ngưỡng an toàn | D13: Plan v5 B7.1; code SENSITIVITY_ROWS (16 dòng)
A14: Kich_ban_do_nhay!A67:B67 → A72:B72 | B14: Ô trợ giúp "Thu nhập TB 2020–2021" ở B67 | C14: Chuyển sang B72, sửa chú thích ở D65 | D14: Nhường chỗ cho dòng độ nhạy mới; công thức không đổi
... A17: Doi_chieu_index_html (sheet mới) | B17: (chưa có) | C17: 48 tham số của index.html V5 đối chiếu với Excel + 13 số listing tính lại từ dữ liệu nhúng | D17: Kiểm tra Excel khớp code; kết quả cột F
